Workbook
Name anzMonate: Einstellungen!$V$5
Name dat_bis: Einstellungen!$H$9
Name dat_von: Einstellungen!$H$8
Name endDat: Einstellungen!$V$2
Name faktor: Einstellungen!$V$3
Name praefix: [1]Einstellungen!$V$4
Name prefix: Einstellungen!$V$4
Name startDat: Einstellungen!$V$1

Sheet Einstellungen
A1: =CONCATENATE("Energieübersicht Schweiz ",E8) -> Energieübersicht Schweiz 2026 | O1: 1 | P1: =MONTH(startDat) -> 1 | Q1: =YEAR(startDat) -> 2026 | R1: 0 | S1: 0 | T1: kW / kWh | U1: Frühstes Datum | V1: 46023
A2: =CONCATENATE("Energy Statistic Switzerland ",E8) -> Energy Statistic Switzerland 2026 | O2: 2 | P2: =IF(AND(P1<=anzMonate,P1<12),P1+1,"") -> 2 | Q2: =IF(Q1<YEAR(endDat),IF(YEAR(startDat)=YEAR(endDat),"",Q1+1),"") -> 2027 | R2: 1 | S2: 15 | T2: MW / MWh | U2: Spätestes Datum | V2: 46388
O3: 3 | P3: 3 | R3: 2 | S3: 30 | U3: Faktor: | V3: =IF(C14="MW / MWh",1,IF(C14="kW / kWh",1000,0)) -> 1
O4: 4 | P4: 4 | R4: 3 | S4: 45 | U4: Prefix: | V4: =IF(C14="MW / MWh","M",IF(C14="kW / kWh","k",0)) -> M
A5: Betrachtungszeitraum | Observation Period | O5: 5 | P5: =IF(AND(P4<=anzMonate,P4<12),P4+1,"") -> 5 | R5: 4 | U5: anzMonate | V5: =MONTH(V2-V1) -> 12
O6: 6 | P6: 6 | R6: 5
C7: DD | D7: MM | E7: YYYY | F7: hh | G7: min | O7: 7 | P7: 7 | R7: 6
A8: Von | From: | C8: 1 | D8: 1 | E8: 2026 | F8: 0 | G8: 0 | H8: =DATE(E8,D8,C8)+TIME(F8,G8,0) -> 46023 | O8: 8 | P8: 8 | R8: 7
A9: Bis | To: | C9: 1 | D9: 2 | E9: 2026 | F9: 0 | G9: 0 | H9: =DATE(E9,D9,C9)+TIME(F9,G9,0) -> 46054 | O9: 9 | P9: 9 | R9: 8
A10: =IF(dat_von>dat_bis,"FEHLER: Startdatum ist grösser als Enddatum",IF(dat_bis>V2+0.001,"FEHLER: Enddatum ist ausserhalb des erlaubten Bereich",IF(dat_von<V1,"FEHLER: Startdatum ist ausserhalb des erlaubten Bereich",""))) | O10: 10 | P10: 10 | R10: 9
O11: 11 | P11: 11 | R11: 10
A12: Einheit | Unit | O12: 12 | P12: 12 | R12: 11
O13: 13 | R13: 12
A14: Ausgewählt | Selected: | C14: MW / MWh | O14: 14 | R14: 13
O15: 15 | R15: 14
O16: 16 | R16: 15
O17: 17 | R17: 16
A18: Anleitung | O18: 18 | R18: 17
O19: 19 | R19: 18
A20: Das hier vorliegende Excel-Sheet beinhaltet die Gesamtübersicht der wichtigsten Eckdaten der Regelzone Schweiz. Die Daten sind aggregierte Viertelstunden, welche zu ihrer Referenz im Blatt «Zeitreihen» abgelegt sind. Ab 2025 sind die Daten linksbündig, das heißt: der Zeitstempel bei "00:00" betrifft das Zeitintervall 00:00 – 00:15. Die Daten sind dieselben, wie auch von Swissgrid zu Abrechnungszwecken verwendet werden. Nebst den Zeitreihen finden Sie auf dem Blatt «Übersicht» die Summen der jeweiligen Energiegrösse welche für den eingestellten Zeitraum direkt berechnet werden. Der Betrachtungszeitraum kann auf dieser Seite eingestellt werden. Achtung: Bei MS-Excel 2003 und älter werden einige Felder nicht automatisch berechnet. Drücken Sie daher STRG+ALT+F9 nachdem Sie die Datei geöffnet haben. | O20: 20 | R20: 19
O21: 21 | R21: 20
O22: 22 | R22: 21
O23: 23 | R23: 22
O24: 24 | R24: 23
O25: 25
O26: 26
O27: 27
O28: 28
O29: 29
O30: 30
A31: Manual | O31: 31
A33: This excel sheet contains a general overview of the most important energy key data of the Swiss control block. You can find 15 Minutes based aggregated time series within the sheets with the naming «Zeitreihen» for your reference. As of 2025, the data is left-aligned, that is: the timestamp at "00:00" concerns the time interval 00:00 - 00:15. The energy data you find there is the same as used by Swissgrid for clearing purposes. Besides the pure time series you can find an overview of all aggregates on sheet «Übersicht», which will be the sum of all values of the selected timeframe. The observated timeframe can be controlled on this page. Attention: In MS-Excel 2003 and older, some calculations aren't performed automatically. Press CTRL+ALT+F9 initially after opening this file.
A44: Erstelldatum: | B44: 16.02.2026 07:34:42

Sheet Datetime
A2: Zeitstempel 0h15
A3: =DATE(MID(Zeitreihen0h15!A3,7,4),MID(Zeitreihen0h15!A3,4,2),LEFT(Zeitreihen0h15!A3,2))+TIME(MID(Zeitreihen0h15!A3,12,2),RIGHT(Zeitreihen0h15!A3,2),0) -> 46023
A4: =DATE(MID(Zeitreihen0h15!A4,7,4),MID(Zeitreihen0h15!A4,4,2),LEFT(Zeitreihen0h15!A4,2))+TIME(MID(Zeitreihen0h15!A4,12,2),RIGHT(Zeitreihen0h15!A4,2),0) -> 46023.01
A5: =DATE(MID(Zeitreihen0h15!A5,7,4),MID(Zeitreihen0h15!A5,4,2),LEFT(Zeitreihen0h15!A5,2))+TIME(MID(Zeitreihen0h15!A5,12,2),RIGHT(Zeitreihen0h15!A5,2),0) -> 46023.021
A6: =DATE(MID(Zeitreihen0h15!A6,7,4),MID(Zeitreihen0h15!A6,4,2),LEFT(Zeitreihen0h15!A6,2))+TIME(MID(Zeitreihen0h15!A6,12,2),RIGHT(Zeitreihen0h15!A6,2),0) -> 46023.031
A7: =DATE(MID(Zeitreihen0h15!A7,7,4),MID(Zeitreihen0h15!A7,4,2),LEFT(Zeitreihen0h15!A7,2))+TIME(MID(Zeitreihen0h15!A7,12,2),RIGHT(Zeitreihen0h15!A7,2),0) -> 46023.042
A8: =DATE(MID(Zeitreihen0h15!A8,7,4),MID(Zeitreihen0h15!A8,4,2),LEFT(Zeitreihen0h15!A8,2))+TIME(MID(Zeitreihen0h15!A8,12,2),RIGHT(Zeitreihen0h15!A8,2),0) -> 46023.052
A9: =DATE(MID(Zeitreihen0h15!A9,7,4),MID(Zeitreihen0h15!A9,4,2),LEFT(Zeitreihen0h15!A9,2))+TIME(MID(Zeitreihen0h15!A9,12,2),RIGHT(Zeitreihen0h15!A9,2),0) -> 46023.062
A10: =DATE(MID(Zeitreihen0h15!A10,7,4),MID(Zeitreihen0h15!A10,4,2),LEFT(Zeitreihen0h15!A10,2))+TIME(MID(Zeitreihen0h15!A10,12,2),RIGHT(Zeitreihen0h15!A10,2),0) -> 46023.073
A11: =DATE(MID(Zeitreihen0h15!A11,7,4),MID(Zeitreihen0h15!A11,4,2),LEFT(Zeitreihen0h15!A11,2))+TIME(MID(Zeitreihen0h15!A11,12,2),RIGHT(Zeitreihen0h15!A11,2),0) -> 46023.083
A12: =DATE(MID(Zeitreihen0h15!A12,7,4),MID(Zeitreihen0h15!A12,4,2),LEFT(Zeitreihen0h15!A12,2))+TIME(MID(Zeitreihen0h15!A12,12,2),RIGHT(Zeitreihen0h15!A12,2),0) -> 46023.094
A13: =DATE(MID(Zeitreihen0h15!A13,7,4),MID(Zeitreihen0h15!A13,4,2),LEFT(Zeitreihen0h15!A13,2))+TIME(MID(Zeitreihen0h15!A13,12,2),RIGHT(Zeitreihen0h15!A13,2),0) -> 46023.104
A14: =DATE(MID(Zeitreihen0h15!A14,7,4),MID(Zeitreihen0h15!A14,4,2),LEFT(Zeitreihen0h15!A14,2))+TIME(MID(Zeitreihen0h15!A14,12,2),RIGHT(Zeitreihen0h15!A14,2),0) -> 46023.115
... A35138: =DATE(MID(Zeitreihen0h15!A35138,7,4),MID(Zeitreihen0h15!A35138,4,2),LEFT(Zeitreihen0h15!A35138,2))+TIME(MID(Zeitreihen0h15!A35138,12,2),RIGHT(Zeitreihen0h15!A35138,2),0) -> #VALUE!

Sheet Uebersicht
A1: =Einstellungen!A1 -> Energieübersicht Schweiz 2026
A3: Periode: | D3: =dat_von -> 46023 | H3: - | I3: =dat_bis -> 46054
A5: Summe produzierte Energie Regelblock Schweiz Total energy production Swiss controlblock | N5: Beschreibung Die Summe der produzierten Energie Regelblock Schweiz ist das Total aller Einspeisegänge der Bilanzgruppen in Viertelstundenauflösung. Diese werden von den Verteilnetzbetreibern an Swissgrid gemeldet. Die Summe beinhaltet sämtliche im Regelblock Schweiz produzierte und ins Netz eingespeiste elektrische Energie. (Nur Produktionen die durch Lastgangmessung erfasst werden) | O5: Description The total of the produced energy in the control block Switzerland. The aggregations of the feed-in sequences for the balancing groups are sent from the distribution network operators to Swissgrid. The sum contains all the energy produced and fed in the network. (Only productions plants equipped with load profile meters)
B8: E | C8: =faktor*1*(SUM(INDIRECT(CONCATENATE("Zeitreihen0h15!$C$",MATCH(dat_von,Datetime!$A:$A,0),":","$C$",MATCH(dat_bis-TIME(0,15,0),Datetime!$A:$A,0)))))/1000 -> 4585185.2 | K8: =CONCATENATE(prefix,"Wh") -> MWh
B9: Pmax | D9: =faktor*4*(MAX(INDIRECT(CONCATENATE("Zeitreihen0h15!$C$",MATCH(dat_von,Datetime!$A:$A,0),":","$C$",MATCH(dat_bis-TIME(0,15,0),Datetime!$A:$A,0)))))/1000 -> 13794.788 | K9: =CONCATENATE(prefix,"W") -> MW
A11: Summe endverbrauchte Energie Regelblock Schweiz Total energy consumed by end users in the Swiss controlblock | N11: Beschreibung Die endverbrauchte Energie oder gemäss VSE Branchendokumente auch «Bruttolastgangsumme des eigenen Netz» (BLS/EN), ist die von den Endverbrauchern in allen Netzebenen bezogene Energie in Viertelstundenauflösung. Diese Summe wird aus den BLS/EN der VNB im Regelblock Schweiz durch Swissgrid gebildet. (Nicht darin enthalten ist die Energie für Pumpen in Pumpspeicherkraftwerken, der Eigenbedarf von Kraftwerken sowie die Netzverluste) | O11: Description The total of the end- user energy consumption includes all aggregates with the end-user consumptions for the Swiss Control block delivered by the distribution network operators to Swissgrid. Not included are grid losses or energy consumed for power plant’s own requirements or to drive the pumps in pumped storage hydro power plant.
B14: E | C14: =faktor*1*(SUM(INDIRECT(CONCATENATE("Zeitreihen0h15!$B$",MATCH(dat_von,Datetime!$A:$A,0),":","$B$",MATCH(dat_bis-TIME(0,15,0),Datetime!$A:$A,0)))))/1000 -> 5743646.6 | K14: =CONCATENATE(prefix,"Wh") -> MWh
B15: Pmax | D15: =faktor*4*(MAX(INDIRECT(CONCATENATE("Zeitreihen0h15!$B$",MATCH(dat_von,Datetime!$A:$A,0),":","$B$",MATCH(dat_bis-TIME(0,15,0),Datetime!$A:$A,0)))))/1000 -> 9948.7229 | K15: =CONCATENATE(prefix,"W") -> MW
A17: Summe verbrauchte Energie Regelblock Schweiz Total energy consumption Swiss controlblock | N17: Beschreibung Die verbrauchte Energie Regelblock Schweiz ist das Total aller Lastgänge der Bilanzgruppen in Viertelstundenauflösung. Diese werden von den Verteilnetzbetreibern an Swissgrid gemeldet. Die Summe beinhaltet sämtliche in der Schweiz aus dem Übertragungsnetz und den Verteilnetzen bezogene elektrische Energie. (Inklusive Verluste, Pumpenergie bei Pumpspeicherkraftwerken und Eigenbedarf von Kraftwerken) | O17: Description The total of the consumed energy in the control block Switzerland. The aggregations of the consumption sequences for the balancing group are sent from the distribution network operators to Swissgrid. The sum contains all the energy consumed in the transmission and distribution grids. Included are grid losses, energy consumed for a power plant’s own requirements and to drive the pumps in pumped storage hydro power plant.
B20: E | C20: =faktor*1*(SUM(INDIRECT(CONCATENATE("Zeitreihen0h15!$D$",MATCH(dat_von,Datetime!$A:$A,0),":","$D$",MATCH(dat_bis-TIME(0,15,0),Datetime!$A:$A,0)))))/1000 -> 6400200.9 | K20: =CONCATENATE(prefix,"Wh") -> MWh
B21: Pmax | D21: =faktor*4*(MAX(INDIRECT(CONCATENATE("Zeitreihen0h15!$D$",MATCH(dat_von,Datetime!$A:$A,0),":","$D$",MATCH(dat_bis-TIME(0,15,0),Datetime!$A:$A,0)))))/1000 -> 10564.969 | K21: =CONCATENATE(prefix,"W") -> MW
A23: Netto Ausspeisung aus dem Übertragungsnetz Schweiz Net outflow of the Swiss transmission grid | N23: Beschreibung Die Netto Ausspeisung aus dem Übertragungsnetz ist die Energiemenge, welche effektiv aus dem Übertragungsnetz über direkt angeschlossene Transformatoren zu nachgelagerten Verteilnetzen, Endverbrauchern und Kraftwerken transportiert wurde. Die Netto Ausspeisung ist der positive Anteil der Bilanzierung aller vertikalen Übergabepunkte im Übertragunsgnetz zu Verteilnetzbetreibern, Endverbrauchern und Kraftwerken. Sie wird in Viertelstundenauflösung und in kWh aufbereitet. | O23: Description The net outflow of the Swiss transmission grid is the amount of energy, which effectively flows over transformers out of the transmission grid into the distribution grids, towards end- users and power plants. The net outflow is the positive part of the netting of the vertical in feeds and outflows of the transmission grid. The resolution is 15 minutes and the energy is shown as kWh
B26: E | C26: =faktor*1*(SUM(INDIRECT(CONCATENATE("Zeitreihen0h15!$E$",MATCH(dat_von,Datetime!$A:$A,0),":","$E$",MATCH(dat_bis-TIME(0,15,0),Datetime!$A:$A,0)))))/1000 -> 1883772.7 | K26: =CONCATENATE(prefix,"Wh") -> MWh
B27: Pmax | D27: =faktor*4*(MAX(INDIRECT(CONCATENATE("Zeitreihen0h15!$E$",MATCH(dat_von,Datetime!$A:$A,0),":","$E$",MATCH(dat_bis-TIME(0,15,0),Datetime!$A:$A,0)))))/1000 -> 5613.1978 | K27: =CONCATENATE(prefix,"W") -> MW
A29: Vertikale Einspeisung ins Übertragungsnetz Schweiz Grid feed-in Swiss transmission grid | N29: Beschreibung Die Summe der vertikalen Einspeisungen errechnet sich aus allen Übergaben ins Übertragungsnetz über direkt angeschlossene Transformatoren und Leitungen von Verteilnetzen und Kraftwerken. Die Summe der vertikalen Einspeisungen wird in Viertelstundenauflösung und in kWh aufbereitet. | O29: Description The total of the vertical in feed into the Swiss Transmission grid is the sum of all time series of production metering points and other in feeds over transformers and lines into the transmission grid. The resolution is 15 minutes and the energy is shown as kWh
B32: E | C32: =faktor*1*(SUM(INDIRECT(CONCATENATE("Zeitreihen0h15!$F$",MATCH(dat_von,Datetime!$A:$A,0),":","$F$",MATCH(dat_bis-TIME(0,15,0),Datetime!$A:$A,0)))))/1000 -> 5022488.2 | K32: =CONCATENATE(prefix,"Wh") -> MWh
B33: Pmax | D33: =faktor*4*(MAX(INDIRECT(CONCATENATE("Zeitreihen0h15!$F$",MATCH(dat_von,Datetime!$A:$A,0),":","$F$",MATCH(dat_bis-TIME(0,15,0),Datetime!$A:$A,0)))))/1000 -> 8264.5752 | K33: =CONCATENATE(prefix,"W") -> MW
A35: Positive Sekundärregelenergie Positive secondary control energy | N35: Beschreibung Die Summe der bezogenen Energiemengen in MWh pro Viertelstunde genettet, welche die Erzeugungseinheiten auf Basis eines SDL-Vertrages und durch Abruf an Swissgrid liefern. | O35: Description The total of the sourced energy which generating units have supplied with secondary control energy Swissgrid based on an ancillary services contract. The energy quantity is a netting of production and consumption in MWh within a 15 minutes time period.
B38: E | C38: =faktor*1*(SUM(INDIRECT(CONCATENATE("Zeitreihen0h15!$G$",MATCH(dat_von,Datetime!$A:$A,0),":","$G$",MATCH(dat_bis-TIME(0,15,0),Datetime!$A:$A,0)))))/1000 -> 14728.716 | K38: =CONCATENATE(prefix,"Wh") -> MWh
B39: Pmax | D39: =faktor*4*(MAX(INDIRECT(CONCATENATE("Zeitreihen0h15!$G$",MATCH(dat_von,Datetime!$A:$A,0),":","$G$",MATCH(dat_bis-TIME(0,15,0),Datetime!$A:$A,0)))))/1000 -> 416.43267 | K39: =CONCATENATE(prefix,"W") -> MW
A41: Negative Sekundärregelenergie Negative secondary control energy | N41: Beschreibung Die Summe der abgegebenen Energiemengen in MWh pro Viertelstunde genettet, welche die Erzeugungseinheiten auf Basis eines SDL-Vertrages und durch Abruf von Swissgrid beziehen. | O41: Description The total of the fed in energy which generating units have sourced with secondary control energy Swissgrid based on an ancillary services contract. The energy quantity is a netting of production and consumption in MWh within a 15 minutes time period.
B44: E | C44: =faktor*1*(SUM(INDIRECT(CONCATENATE("Zeitreihen0h15!$H$",MATCH(dat_von,Datetime!$A:$A,0),":","$H$",MATCH(dat_bis-TIME(0,15,0),Datetime!$A:$A,0)))))/1000 -> -6639.8296 | K44: =CONCATENATE(prefix,"Wh") -> MWh
B45: Pmax | D45: =faktor*4*(MIN(INDIRECT(CONCATENATE("Zeitreihen0h15!$H$",MATCH(dat_von,Datetime!$A:$A,0),":","$H$",MATCH(dat_bis-TIME(0,15,0),Datetime!$A:$A,0)))))/1000 -> -264.21009 | K45: =CONCATENATE(prefix,"W") -> MW
A47: Positive Tertiärregelenergie Positive tertiary control energy | N47: Beschreibung Die Summe der bezogenen Energiemengen in MWh pro Viertelstunde, welche die Erzeugungseinheiten auf Basis eines SDL-Vertrages und durch Tertiärabruf an Swissgrid liefern. | O47: Description The total of the sourced energy which generating units have supplied with tertiary control energy Swissgrid based on an ancillary services contract.
B50: E | C50: =faktor*1*(SUM(INDIRECT(CONCATENATE("Zeitreihen0h15!$I$",MATCH(dat_von,Datetime!$A:$A,0),":","$I$",MATCH(dat_bis-TIME(0,15,0),Datetime!$A:$A,0)))))/1000 -> 55413.5 | K50: =CONCATENATE(prefix,"Wh") -> MWh
B51: Pmax | D51: =faktor*4*(MAX(INDIRECT(CONCATENATE("Zeitreihen0h15!$I$",MATCH(dat_von,Datetime!$A:$A,0),":","$I$",MATCH(dat_bis-TIME(0,15,0),Datetime!$A:$A,0)))))/1000 -> 881 | K51: =CONCATENATE(prefix,"W") -> MW
A53: Negative Tertiärregelenergie Negative tertiary control energy | N53: Beschreibung Die Summe der abgegebenen Energiemengen in MWh pro Viertelstunde, welche die Erzeugungseinheiten auf Basis eines SDL-Vertrages und durch Tertiärabruf von Swissgrid beziehen | O53: Description The total of the fed in energy which generating units have sourced with tertiary control energy Swissgrid based on an ancillary services contract.
B56: E | C56: =faktor*1*(SUM(INDIRECT(CONCATENATE("Zeitreihen0h15!$J$",MATCH(dat_von,Datetime!$A:$A,0),":","$J$",MATCH(dat_bis-TIME(0,15,0),Datetime!$A:$A,0)))))/1000 -> -19999 | K56: =CONCATENATE(prefix,"Wh") -> MWh
B57: Pmax | D57: =faktor*4*(MIN(INDIRECT(CONCATENATE("Zeitreihen0h15!$J$",MATCH(dat_von,Datetime!$A:$A,0),":","$J$",MATCH(dat_bis-TIME(0,15,0),Datetime!$A:$A,0)))))/1000 -> -538 | K57: =CONCATENATE(prefix,"W") -> MW
A59: Regelenergiepreise Control energy prices | N59: Beschreibung Durchschnittliche Regelenergiepreise pro Viertelstunde auf zwei Nachkommastellen gerundet für die Produkte Sekundär- und Tertiärregelenergie. | O59: Description Average prices of control energy per 15 minutes rounded to two decimal places for secondary and tertiary control energy products.
B62: Siehe Blatt mit den Zeitreihen
B63: See sheet with timeseries
A66: Verbundaustausch Cross Border Exchange | N66: Die Pfeilrichtungen dienen nur zur Illustration und müssen keiner echten Energierichtung entsprechen Directions of arrows only ilustrate the meaning and have no link to real energy flows
B69: CH→AT | D69: E | E69: =faktor*1*(SUM(INDIRECT(CONCATENATE("Zeitreihen0h15!$K$",MATCH(dat_von,Datetime!$A:$A,0),":","$K$",MATCH(dat_bis-TIME(0,15,0),Datetime!$A:$A,0)))))/1000 -> 415357.87 | K69: =CONCATENATE(prefix,"Wh") -> MWh
D70: Pmax | E70: =faktor*4*(MAX(INDIRECT(CONCATENATE("Zeitreihen0h15!$K$",MATCH(dat_von,Datetime!$A:$A,0),":","$K$",MATCH(dat_bis-TIME(0,15,0),Datetime!$A:$A,0)))))/1000 -> 1996.38 | K70: =CONCATENATE(prefix,"W") -> MW
B71: AT→CH | D71: E | E71: =faktor*1*(SUM(INDIRECT(CONCATENATE("Zeitreihen0h15!$L$",MATCH(dat_von,Datetime!$A:$A,0),":","$L$",MATCH(dat_bis-TIME(0,15,0),Datetime!$A:$A,0)))))/1000 -> 222329.91 | K71: =CONCATENATE(prefix,"Wh") -> MWh
D72: Pmax | E72: =faktor*4*(MAX(INDIRECT(CONCATENATE("Zeitreihen0h15!$L$",MATCH(dat_von,Datetime!$A:$A,0),":","$L$",MATCH(dat_bis-TIME(0,15,0),Datetime!$A:$A,0)))))/1000 -> 1696.272 | K72: =CONCATENATE(prefix,"W") -> MW
B74: CH→DE | D74: E | E74: =faktor*1*(SUM(INDIRECT(CONCATENATE("Zeitreihen0h15!$M$",MATCH(dat_von,Datetime!$A:$A,0),":","$M$",MATCH(dat_bis-TIME(0,15,0),Datetime!$A:$A,0)))))/1000 -> 304781.29 | K74: =CONCATENATE(prefix,"Wh") -> MWh
D75: Pmax | E75: =faktor*4*(MAX(INDIRECT(CONCATENATE("Zeitreihen0h15!$M$",MATCH(dat_von,Datetime!$A:$A,0),":","$M$",MATCH(dat_bis-TIME(0,15,0),Datetime!$A:$A,0)))))/1000 -> 3250.304 | K75: =CONCATENATE(prefix,"W") -> MW
B76: DE→CH | D76: E | E76: =faktor*1*(SUM(INDIRECT(CONCATENATE("Zeitreihen0h15!$N$",MATCH(dat_von,Datetime!$A:$A,0),":","$N$",MATCH(dat_bis-TIME(0,15,0),Datetime!$A:$A,0)))))/1000 -> 1498581.9 | K76: =CONCATENATE(prefix,"Wh") -> MWh
...

Sheet Zeitreihen0h15
B1: Summe endverbrauchte Energie Regelblock Schweiz Total energy consumed by end users in the Swiss controlblock | C1: Summe produzierte Energie Regelblock Schweiz Total energy production Swiss controlblock | D1: Summe verbrauchte Energie Regelblock Schweiz Total energy consumption Swiss controlblock | E1: Netto Ausspeisung aus dem Übertragungsnetz Schweiz Net outflow of the Swiss transmission grid | F1: Vertikale Einspeisung ins Übertragungsnetz Schweiz Grid feed-in Swiss transmission grid | G1: Positive Sekundär-Regelenergie Positive secundary control energy | H1: Negative Sekundär-Regelenergie Negative secundary control energy | I1: Positive Tertiär-Regelenergie Positive tertiary control energy | J1: Negative Tertiär-Regelenergie Negative tertiary control energy | K1: Verbundaustausch CH->AT Cross Border Exchange CH->AT | L1: Verbundaustausch AT->CH Cross Border Exchange AT->CH | M1: Verbundaustausch CH->DE Cross Border Exchange CH->DE | N1: Verbundaustausch DE->CH Cross Border Exchange DE->CH | O1: Verbundaustausch CH->FR Cross Border Exchange CH->FR | P1: Verbundaustausch FR->CH Cross Border Exchange FR->CH | Q1: Verbundaustausch CH->IT Cross Border Exchange CH->IT | R1: Verbundaustausch IT->CH Cross Border Exchange IT->CH | S1: Transit | T1: Import | U1: Export | V1: Durchschnittliche positive Sekundär-Regelenergie Preise Average positive secondary control energy prices | W1: Durchschnittliche negative Sekundär-Regelenergie Preise Average negative secondary control energy prices | X1: Durchschnittliche positive Tertiär-Regelenergie Preise Average positive tertiary control energy prices | Y1: Durchschnittliche negative Tertiär-Regelenergie Preise Average negative tertiary control energy prices | Z1: Produktion Kanton AG Production Canton AG | AA1: Verbrauch Kanton AG Consumption Canton AG | AB1: Produktion Kanton FR Production Canton FR | AC1: Verbrauch Kanton FR Consumption Canton FR | AD1: Produktion Kanton GL Production Canton GL | AE1: Verbrauch Kanton GL Consumption Canton GL | AF1: Produktion Kanton GR Production Canton GR | AG1: Verbrauch Kanton GR Consumption Canton GR | AH1: Produktion Kanton LU Production Canton LU | AI1: Verbrauch Kanton LU Consumption Canton LU | AJ1: Produktion Kanton NE Production Canton NE | AK1: Verbrauch Kanton NE Consumption Canton NE | AL1: Produktion Kanton SO Production Canton SO | AM1: Verbrauch Kanton SO Consumption Canton SO | AN1: Produktion Kanton SG Production Canton SG | AO1: Verbrauch Kanton SG Consumption Canton SG | AP1: Produktion Kanton TI Production Canton TI | AQ1: Verbrauch Kanton TI Consumption Canton TI | AR1: Produktion Kanton TG Production Canton TG | AS1: Verbrauch Kanton TG Consumption Canton TG | AT1: Produktion Kanton VS Production Canton VS | AU1: Verbrauch Kanton VS Consumption Canton VS | AV1: Produktion Kantone AI, AR Production Cantons AI, AR | AW1: Verbrauch Kantone AI, AR Consumption Cantons AI, AR | AX1: Produktion Kantone BL, BS Production Cantons BL, BS | AY1: Verbrauch Kantone BL, BS Consumption Cantons BL, BS | AZ1: Produktion Kantone BE, JU Production Cantons BE, JU | BA1: Verbrauch Kantone BE, JU Consumption Cantons BE, JU | BB1: Produktion Kantone SZ, ZG Production Cantons SZ, ZG | BC1: Verbrauch Kantone SZ, ZG Consumption Cantons SZ, ZG | BD1: Produktion Kantone OW, NW, UR Production Cantons OW, NW, UR | BE1: Verbrauch Kantone OW, NW, UR Consumption Cantons OW, NW, UR | BF1: Produktion Kantone GE, VD Production Cantons GE, VD | BG1: Verbrauch Kantone GE, VD Consumption Cantons GE, VD | BH1: Produktion Kantone SH, ZH Production Cantons SH, ZH | BI1: Verbrauch Kantone SH, ZH Consumption Cantons SH, ZH | BJ1: Produktion Kantonsübergreifend Production across Cantons | BK1: Verbrauch Kantonsübergreifend Consumption across Cantons | BL1: Produktion Regelzone CH - Ausländische Gebiete Production control area CH - foreign territories | BM1: Verbrauch Regelzone CH - Ausländische Gebiete Consumption control area CH - foreign territories
A2: Zeitstempel | B2: kWh | C2: kWh | D2: kWh | E2: kWh | F2: kWh | G2: kWh | H2: kWh | I2: kWh | J2: kWh | K2: kWh | L2: kWh | M2: kWh | N2: kWh | O2: kWh | P2: kWh | Q2: kWh | R2: kWh | S2: kWh | T2: kWh | U2: kWh | V2: Euro/MWh | W2: Euro/MWh | X2: Euro/MWh | Y2: Euro/MWh | Z2: kWh | AA2: kWh | AB2: kWh | AC2: kWh | AD2: kWh | AE2: kWh | AF2: kWh | AG2: kWh | AH2: kWh | AI2: kWh | AJ2: kWh | AK2: kWh | AL2: kWh | AM2: kWh | AN2: kWh | AO2: kWh | AP2: kWh | AQ2: kWh | AR2: kWh | AS2: kWh | AT2: kWh | AU2: kWh | AV2: kWh | AW2: kWh | AX2: kWh | AY2: kWh | AZ2: kWh | BA2: kWh | BB2: kWh | BC2: kWh | BD2: kWh | BE2: kWh | BF2: kWh | BG2: kWh | BH2: kWh | BI2: kWh | BJ2: kWh | BK2: kWh | BL2: kWh | BM2: kWh
A3: 01.01.2026 00:00 | B3: 1792608.3 | C3: 1035890 | D3: 1920033.9 | E3: 852572.8 | F3: 1587766.1 | G3: 276.646 | H3: -6260.1 | I3: 62250 | J3: 0 | K3: 50300 | L3: 186429 | M3: 6900 | N3: 979386 | O3: 140664 | P3: 311790 | Q3: 429986 | R3: 36042 | S3: 627850 | T3: 1513647 | U3: 627850 | V3: 169 | W3: -70.11 | X3: 124.27341 | Y3: 0 | Z3: 505796.03 | AA3: 165992.52 | AB3: 7710.187 | AC3: 95210.343 | AD3: 2725.773 | AE3: 12072.091 | AF3: 97152.743 | AG3: 87805.828 | AH3: 7768.78 | AI3: 95431.284 | AJ3: 195.625 | AK3: 14857.323 | AL3: 6280.459 | AM3: 43664.263 | AN3: 8994.8756 | AO3: 99872.236 | AP3: 67083.251 | AQ3: 84040.098 | AR3: 2715.889 | AS3: 55392.089 | AT3: 145791.55 | AU3: 115389.66 | AV3: 495.2714 | AW3: 18239.083 | AX3: 17352.51 | AY3: 95452.405 | AZ3: 48039.17 | BA3: 257086.67 | BB3: 5683.503 | BC3: 62147.063 | BD3: 9346.665 | BE3: 34659.664 | BF3: 20366.866 | BG3: 204287.76 | BH3: 19881.538 | BI3: 305204.31 | BJ3: 59820.252 | BK3: 56918.421 | BL3: 2689.037 | BM3: 16310.786
A4: 01.01.2026 00:15 | B4: 1791121.5 | C4: 1041749.6 | D4: 1912134.4 | E4: 838874.46 | F4: 1583967.8 | G4: 78.296 | H4: -14551.848 | I4: 55500 | J4: 0 | K4: 30400 | L4: 183792 | M4: 6900 | N4: 968870 | O4: 154771 | P4: 301123 | Q4: 428417 | R4: 39796 | S4: 620488 | T4: 1493581 | U4: 620488 | V4: 169 | W4: -91.21 | X4: 124.06194 | Y4: 0 | Z4: 505988.49 | AA4: 168115.81 | AB4: 7679.983 | AC4: 96011.861 | AD4: 2561.057 | AE4: 11965.973 | AF4: 106049.22 | AG4: 87686.854 | AH4: 7752.896 | AI4: 95119.879 | AJ4: 283.898 | AK4: 14607.556 | AL4: 5769.453 | AM4: 43567.374 | AN4: 9010.311 | AO4: 98705.215 | AP4: 69903.404 | AQ4: 83570.995 | AR4: 2693.037 | AS4: 55716.258 | AT4: 148030.64 | AU4: 114792.86 | AV4: 488.176 | AW4: 17965.825 | AX4: 17211.354 | AY4: 96584.747 | AZ4: 41580.321 | BA4: 254592.33 | BB4: 5597.133 | BC4: 61831.51 | BD4: 9269.422 | BE4: 34264.421 | BF4: 20351.59 | BG4: 198185.51 | BH4: 19872.383 | BI4: 306526.34 | BJ4: 58947.632 | BK4: 56315.213 | BL4: 2709.183 | BM4: 16007.86
A5: 01.01.2026 00:30 | B5: 1785786.4 | C5: 1033622.1 | D5: 1903251.4 | E5: 838423.47 | F5: 1568106.8 | G5: 1245.533 | H5: -2887.825 | I5: 36000 | J5: 0 | K5: 25800 | L5: 174134 | M5: 7400 | N5: 921505 | O5: 149355 | P5: 277321 | Q5: 373633 | R5: 54546 | S5: 556188 | T5: 1427506 | U5: 556188 | V5: 169.18 | W5: -56.5 | X5: 123.57208 | Y5: 0 | Z5: 505982.12 | AA5: 168356.98 | AB5: 7593.212 | AC5: 95663.911 | AD5: 2636.556 | AE5: 11818.221 | AF5: 109424.7 | AG5: 87406.527 | AH5: 8069.771 | AI5: 96904.154 | AJ5: 322.293 | AK5: 14216.753 | AL5: 5749.293 | AM5: 44027.872 | AN5: 9019.2078 | AO5: 96654.028 | AP5: 68450.597 | AQ5: 82046.449 | AR5: 2694.993 | AS5: 55827.667 | AT5: 134240.91 | AU5: 114345.3 | AV5: 488.5742 | AW5: 17653.815 | AX5: 16226.856 | AY5: 96768.051 | AZ5: 45684.386 | BA5: 256205.83 | BB5: 5330.437 | BC5: 61980.549 | BD5: 9178.177 | BE5: 34009.177 | BF5: 20183.228 | BG5: 196245.09 | BH5: 19842.121 | BI5: 301937.95 | BJ5: 59857.262 | BK5: 55394.587 | BL5: 2647.381 | BM5: 15788.466
A6: 01.01.2026 00:45 | B6: 1771784.4 | C6: 1018971 | D6: 1911990.8 | E6: 863122.13 | F6: 1571485.5 | G6: 9247.225 | H6: -1.845 | I6: 15000 | J6: 0 | K6: 29500 | L6: 171165 | M6: 7300 | N6: 922016 | O6: 120704 | P6: 285463 | Q6: 380000 | R6: 53425 | S6: 537504 | T6: 1432069 | U6: 537504 | V6: 149.21 | W6: 20 | X6: 122.89 | Y6: 0 | Z6: 505951.56 | AA6: 166860.77 | AB6: 7556.801 | AC6: 95579.425 | AD6: 4326.271 | AE6: 11845.124 | AF6: 105131.89 | AG6: 86396.929 | AH6: 10225.489 | AI6: 97977.596 | AJ6: 315.516 | AK6: 13998.768 | AL6: 5745.454 | AM6: 43779.885 | AN6: 12023.253 | AO6: 94877.753 | AP6: 66579.388 | AQ6: 81478.072 | AR6: 2871.347 | AS6: 55398.326 | AT6: 124737.25 | AU6: 135998.52 | AV6: 1529.2506 | AW6: 17292.286 | AX6: 15510.227 | AY6: 95971.367 | AZ6: 44107.356 | BA6: 254970.17 | BB6: 5113.748 | BC6: 61020.59 | BD6: 5662.543 | BE6: 33551.541 | BF6: 19775.101 | BG6: 196222.69 | BH6: 19950.165 | BI6: 300256.56 | BJ6: 59304.905 | BK6: 52838.875 | BL6: 2553.467 | BM6: 15675.591
A7: 01.01.2026 01:00 | B7: 1784547.7 | C7: 1031557.6 | D7: 1977453.3 | E7: 912235.8 | F7: 1626959.1 | G7: 18603.847 | H7: 0 | I7: 47500 | J7: 0 | K7: 11800 | L7: 182141 | M7: 7000 | N7: 946454 | O7: 122153 | P7: 283479 | Q7: 385463 | R7: 61227 | S7: 526416 | T7: 1473301 | U7: 526416 | V7: 158.72 | W7: 0 | X7: 124.42211 | Y7: 0 | Z7: 505565.91 | AA7: 169727.84 | AB7: 8103.113 | AC7: 100419.95 | AD7: 3700.366 | AE7: 11697.164 | AF7: 118439.3 | AG7: 88653.052 | AH7: 11490.055 | AI7: 96683.969 | AJ7: 323.933 | AK7: 13820.102 | AL7: 5717.954 | AM7: 44648.435 | AN7: 12944.285 | AO7: 97105.581 | AP7: 58867.876 | AQ7: 82825.908 | AR7: 2865.445 | AS7: 55811.184 | AT7: 120847.56 | AU7: 141551.58 | AV7: 1954.6242 | AW7: 17987.593 | AX7: 15436.445 | AY7: 96331.196 | AZ7: 50428.217 | BA7: 276816.35 | BB7: 5596.819 | BC7: 61951.756 | BD7: 5363.777 | BE7: 34294.776 | BF7: 21171.173 | BG7: 222292.52 | BH7: 19858.64 | BI7: 297235.47 | BJ7: 60303.634 | BK7: 51462.831 | BL7: 2578.432 | BM7: 16136.088
A8: 01.01.2026 01:15 | B8: 1770919 | C8: 1013787.8 | D8: 1964499.8 | E8: 918953.47 | F8: 1618833.5 | G8: 13447.604 | H8: 0 | I8: 35000 | J8: 0 | K8: 16500 | L8: 171951 | M8: 7100 | N8: 932573 | O8: 102755 | P8: 292878 | Q8: 380045 | R8: 61152 | S8: 506400 | T8: 1458554 | U8: 506400 | V8: 153.18 | W8: 0 | X8: 124.03714 | Y8: 0 | Z8: 505664.17 | AA8: 170273.35 | AB8: 9165.555 | AC8: 98502.444 | AD8: 3104.552 | AE8: 12240.179 | AF8: 118200.63 | AG8: 87874.314 | AH8: 10772.882 | AI8: 97171.906 | AJ8: 315.152 | AK8: 13701.92 | AL8: 5715.217 | AM8: 44367.3 | AN8: 12372.768 | AO8: 95713.933 | AP8: 56010.001 | AQ8: 82187.543 | AR8: 2858.307 | AS8: 55348.155 | AT8: 107021.28 | AU8: 141602.86 | AV8: 1823.1474 | AW8: 17703.117 | AX8: 15710.973 | AY8: 97328.737 | AZ8: 49540.054 | BA8: 276705.4 | BB8: 5454.487 | BC8: 60687.159 | BD8: 5598.682 | BE8: 33694.681 | BF8: 20974.56 | BG8: 221119.49 | BH8: 20433.376 | BI8: 292423.64 | BJ8: 60403.837 | BK8: 49646.553 | BL8: 2648.179 | BM8: 16207.126
A9: 01.01.2026 01:30 | B9: 1760993.5 | C9: 1015423.1 | D9: 1956141.1 | E9: 906378.47 | F9: 1617565.1 | G9: 9895.585 | H9: 0 | I9: 40000 | J9: 0 | K9: 5900 | L9: 189777 | M9: 6600 | N9: 977922 | O9: 136645 | P9: 278501 | Q9: 411323 | R9: 56290 | S9: 560468 | T9: 1502490 | U9: 560468 | V9: 172.83 | W9: 0 | X9: 124.1575 | Y9: 0 | Z9: 505577.28 | AA9: 167970.09 | AB9: 8620.326 | AC9: 95965.367 | AD9: 3542.673 | AE9: 12264.862 | AF9: 114348.39 | AG9: 86699.297 | AH9: 10150.595 | AI9: 99943.753 | AJ9: 321.706 | AK9: 13364.646 | AL9: 5722.845 | AM9: 43816.943 | AN9: 8739.7654 | AO9: 95011.294 | AP9: 54451.268 | AQ9: 81659.636 | AR9: 2648.765 | AS9: 54800.095 | AT9: 122175.91 | AU9: 140940.82 | AV9: 507.1526 | AW9: 17433.088 | AX9: 15866.066 | AY9: 97372.175 | AZ9: 47906.349 | BA9: 276851.54 | BB9: 5225.267 | BC9: 60418.992 | BD9: 5196.912 | BE9: 33688.912 | BF9: 20951.536 | BG9: 218687.79 | BH9: 20476.276 | BI9: 291318.69 | BJ9: 60365.932 | BK9: 52048.258 | BL9: 2628.089 | BM9: 15884.846
A10: 01.01.2026 01:45 | B10: 1740391.3 | C10: 996861.68 | D10: 1936001.6 | E10: 907748.47 | F10: 1601398.5 | G10: 10696.951 | H10: -0.574 | I10: 27500 | J10: 0 | K10: 12700 | L10: 184669 | M10: 6700 | N10: 970175 | O10: 126148 | P10: 284683 | Q10: 407302 | R10: 53975 | S10: 552850 | T10: 1493502 | U10: 552850 | V10: 177.06 | W10: 16.42 | X10: 123.37455 | Y10: 0 | Z10: 505527.03 | AA10: 164678.45 | AB10: 7981.11 | AC10: 93037.667 | AD10: 3597.87 | AE10: 11861.618 | AF10: 108544 | AG10: 85452.369 | AH10: 8556.794 | AI10: 98034.666 | AJ10: 315.624 | AK10: 13223.895 | AL10: 5711.397 | AM10: 43318.863 | AN10: 9369.8236 | AO10: 93565.712 | AP10: 52138.112 | AQ10: 80886.521 | AR10: 2711.272 | AS10: 54301.095 | AT10: 109442.36 | AU10: 141799.12 | AV10: 585.9524 | AW10: 16997.816 | AX10: 16330.273 | AY10: 96853.393 | AZ10: 49944.073 | BA10: 273553.04 | BB10: 5079.38 | BC10: 59297.875 | BD10: 5036.255 | BE10: 33333.256 | BF10: 22428.635 | BG10: 216762.69 | BH10: 19818.993 | BI10: 292293.95 | BJ10: 60999.727 | BK10: 50779.306 | BL10: 2742.999 | BM10: 15970.304
A11: 01.01.2026 02:00 | B11: 1746028.7 | C11: 1023302.4 | D11: 1974494.6 | E11: 916918.14 | F11: 1637511.5 | G11: 15023.413 | H11: 0 | I11: 54250 | J11: 0 | K11: 24800 | L11: 168857 | M11: 6700 | N11: 976400 | O11: 139658 | P11: 293460 | Q11: 381054 | R11: 66247 | S11: 552212 | T11: 1504964 | U11: 552212 | V11: 182.93 | W11: 0 | X11: 122.17097 | Y11: 0 | Z11: 505584.32 | AA11: 164272.35 | AB11: 7968.508 | AC11: 90740.238 | AD11: 3615.571 | AE11: 11695.614 | AF11: 122839.14 | AG11: 85330.651 | AH11: 9490.524 | AI11: 97074.855 | AJ11: 313.849 | AK11: 13305.29 | AL11: 5713.497 | AM11: 43447.398 | AN11: 9255.4162 | AO11: 96588.453 | AP11: 51868.372 | AQ11: 79984.407 | AR11: 2677.932 | AS11: 54834.572 | AT11: 115492.32 | AU11: 164015.44 | AV11: 489.9768 | AW11: 17441.48 | AX11: 17014.264 | AY11: 95291.099 | AZ11: 54013.752 | BA11: 264025.51 | BB11: 4921.014 | BC11: 60179.135 | BD11: 5340.788 | BE11: 33823.788 | BF11: 21413.521 | BG11: 238282.94 | BH11: 20144.886 | BI11: 299943.75 | BJ11: 62327.732 | BK11: 48431.833 | BL11: 2817.009 | BM11: 15785.753
A12: 01.01.2026 02:15 | B12: 1723292.8 | C12: 1003441.6 | D12: 1956695.2 | E12: 919825.8 | F12: 1631039.1 | G12: 5397.281 | H12: -594.724 | I12: 49250 | J12: 0 | K12: 29500 | L12: 166490 | M12: 6800 | N12: 942908 | O12: 135721 | P12: 302704 | Q12: 356514 | R12: 71201 | S12: 528535 | T12: 1483303 | U12: 528535 | V12: 172.56 | W12: 30.87 | X12: 121.88376 | Y12: 0 | Z12: 505618.08 | AA12: 161896.95 | AB12: 8125.91 | AC12: 89133.178 | AD12: 3531.463 | AE12: 11486.59 | AF12: 121964.89 | AG12: 83646.696 | AH12: 8434.242 | AI12: 95384.01 | AJ12: 311.606 | AK12: 13221.86 | AL12: 5672.444 | AM12: 43112.129 | AN12: 8654.5556 | AO12: 94806.002 | AP12: 50343.123 | AQ12: 79439.433 | AR12: 2666.058 | AS12: 54317.286 | AT12: 103645.48 | AU12: 163573.99 | AV12: 486.3804 | AW12: 17009.59 | AX12: 17395.411 | AY12: 93561.703 | AZ12: 50994.443 | BA12: 262068.88 | BB12: 4735.923 | BC12: 59014.446 | BD12: 5111.076 | BE12: 33185.077 | BF12: 21268.87 | BG12: 244612.43 | BH12: 19663.677 | BI12: 294569.39 | BJ12: 62019.52 | BK12: 47014.472 | BL12: 2798.471 | BM12: 15641.119
A13: 01.01.2026 02:30 | B13: 1707938 | C13: 991461.35 | D13: 1943611 | E13: 915857.13 | F13: 1617713.8 | G13: 4769.156 | H13: -40.264 | I13: 44250 | J13: 0 | K13: 23500 | L13: 187051 | M13: 6500 | N13: 989470 | O13: 149431 | P13: 309022 | Q13: 415106 | R13: 63127 | S13: 594537 | T13: 1548670 | U13: 594537 | V13: 164.54 | W13: 32.2 | X13: 121.54294 | Y13: 0 | Z13: 505564.07 | AA13: 159817.23 | AB13: 8033.295 | AC13: 87783.777 | AD13: 3371.734 | AE13: 11318.928 | AF13: 117847.11 | AG13: 82305.289 | AH13: 7872.302 | AI13: 95292.232 | AJ13: 314.93 | AK13: 12946.501 | AL13: 5660.19 | AM13: 42097.078 | AN13: 9428.7454 | AO13: 93591.641 | AP13: 48226.253 | AQ13: 78423.957 | AR13: 2700.412 | AS13: 53661.117 | AT13: 95387.06 | AU13: 163064.64 | AV13: 791.3236 | AW13: 16558.096 | AX13: 17615.276 | AY13: 92543.455 | AZ13: 50856.39 | BA13: 263142.77 | BB13: 4647.634 | BC13: 57980.839 | BD13: 7618.854 | BE13: 32108.855 | BF13: 21262.355 | BG13: 243932.07 | BH13: 19536.114 | BI13: 292186.04 | BJ13: 61885.148 | BK13: 49315.184 | BL13: 2842.149 | BM13: 15541.317
A14: 01.01.2026 02:45 | B14: 1684041 | C14: 976950.11 | D14: 1919686.8 | E14: 907553.8 | F14: 1599070.5 | G14: 1687.928 | H14: -483.678 | I14: 31250 | J14: 0 | K14: 26200 | L14: 186079 | M14: 6300 | N14: 997336 | O14: 139573 | P14: 314915 | Q14: 438130 | R14: 56669 | S14: 610203 | T14: 1554999 | U14: 610203 | V14: 163.02 | W14: 17.89 | X14: 120.204 | Y14: 0 | Z14: 505657.74 | AA14: 157690.54 | AB14: 7859.498 | AC14: 86331.204 | AD14: 3271.098 | AE14: 11018.717 | AF14: 114560.47 | AG14: 81431.025 | AH14: 7607.484 | AI14: 93728.093 | AJ14: 310.386 | AK14: 12893.026 | AL14: 5617.673 | AM14: 41297.225 | AN14: 8607.5508 | AO14: 91368.28 | AP14: 45417.874 | AQ14: 78152.982 | AR14: 3299.298 | AS14: 53236.86 | AT14: 88156.979 | AU14: 162536.38 | AV14: 487.7962 | AW14: 16057.982 | AX14: 17299.703 | AY14: 90643.177 | AZ14: 49412.089 | BA14: 261941.34 | BB14: 4634.875 | BC14: 56639.975 | BD14: 9063.785 | BE14: 31796.785 | BF14: 21300.76 | BG14: 241735.71 | BH14: 19485.599 | BI14: 285624.98 | BJ14: 62152.79 | BK14: 50290.089 | BL14: 2746.658 | BM14: 15272.432
... A2978: 31.01.2026 23:45 | B2978: 1685817.4 | C2978: 904460.44 | D2978: 2058481.3 | E2978: 1119456.8 | F2978: 1726226.8 | G2978: 13602.834 | H2978: -833.703 | I2978: 5750 | J2978: 0 | K2978: 48500 | L2978: 173588 | M2978: 9200 | N2978: 753430 | O2978: 39500 | P2978: 703481 | Q2978: 396145 | R2978: 18157 | S2978: 493345 | T2978: 1648656 | U2978: 493345 | V2978: 248.74 | W2978: 89 | X2978: 146.92217 | Y2978: 0 | Z2978: 508124.33 | AA2978: 142112.25 | AB2978: 11378.625 | AC2978: 87385.536 | AD2978: 8052.989 | AE2978: 145338.2 | AF2978: 37035.249 | AG2978: 71298.241 | AH2978: 10066.875 | AI2978: 102639.27 | AJ2978: 427.927 | AK2978: 15596.187 | AL2978: 9530.319 | AM2978: 39977.267 | AN2978: 9302.6392 | AO2978: 91118.132 | AP2978: 11726.41 | AQ2978: 85587.294 | AR2978: 4674.183 | AS2978: 49518.37 | AT2978: 83666.747 | AU2978: 158340.21 | AV2978: 621.5288 | AW2978: 15025.615 | AX2978: 19416.249 | AY2978: 88414.029 | AZ2978: 61763.97 | BA2978: 257670.43 | BB2978: 4077.916 | BC2978: 54283.416 | BD2978: 6529.104 | BE2978: 28253.104 | BF2978: 29171.584 | BG2978: 256853.37 | BH2978: 18543.784 | BI2978: 280663.67 | BJ2978: 67517.424 | BK2978: 72170.509 | BL2978: 2832.591 | BM2978: 16236.197
